Traceback (most recent call last):
  File "/home/heloisamengisztki/.local/lib/python3.10/site-packages/tables_io/ioUtils.py", line 778, in readPqToDataFrames
    dataframes[key] = readPqToDataFrame(f"{basepath}{key}.pq")
  File "/home/heloisamengisztki/.local/lib/python3.10/site-packages/tables_io/ioUtils.py", line 733, in readPqToDataFrame
    return pd.read_parquet(filepath, engine='pyarrow')
  File "/home/heloisamengisztki/.local/lib/python3.10/site-packages/pandas/io/parquet.py", line 501, in read_parquet
    return impl.read(
  File "/home/heloisamengisztki/.local/lib/python3.10/site-packages/pandas/io/parquet.py", line 242, in read
    path_or_handle, handles, kwargs["filesystem"] = _get_path_or_handle(
  File "/home/heloisamengisztki/.local/lib/python3.10/site-packages/pandas/io/parquet.py", line 102, in _get_path_or_handle
    handles = get_handle(
  File "/home/heloisamengisztki/.local/lib/python3.10/site-packages/pandas/io/common.py", line 866, in get_handle
    handle = open(handle, ioargs.mode)
FileNotFoundError: [Errno 2] No such file or directory: 'inprogress_output_col_remapper_train.pq'

The above exception was the direct cause of the following exception:

Traceback (most recent call last):
  File "/opt/lsst/software/stack/conda/miniconda3-py38_4.9.2/envs/lsst-scipipe-4.1.0/lib/python3.10/runpy.py", line 196, in _run_module_as_main
    return _run_code(code, main_globals, None,
  File "/opt/lsst/software/stack/conda/miniconda3-py38_4.9.2/envs/lsst-scipipe-4.1.0/lib/python3.10/runpy.py", line 86, in _run_code
    exec(code, run_globals)
  File "/home/heloisamengisztki/.local/lib/python3.10/site-packages/ceci/__main__.py", line 5, in <module>
    PipelineStage.main()
  File "/home/heloisamengisztki/.local/lib/python3.10/site-packages/ceci/stage.py", line 469, in main
    stage.execute(args)
  File "/home/heloisamengisztki/.local/lib/python3.10/site-packages/ceci/stage.py", line 604, in execute
    stage.run()
  File "/home/heloisamengisztki/.local/lib/python3.10/site-packages/rail/estimation/algos/bpz_lite.py", line 202, in run
    training_data = self.get_data('input')
  File "/home/heloisamengisztki/.local/lib/python3.10/site-packages/rail/core/stage.py", line 247, in get_data
    handle.read()
  File "/home/heloisamengisztki/.local/lib/python3.10/site-packages/rail/core/data.py", line 62, in read
    self.set_data(self._read(self.path, **kwargs))
  File "/home/heloisamengisztki/.local/lib/python3.10/site-packages/rail/core/data.py", line 205, in _read
    return tables_io.read(path, **kwargs)
  File "/home/heloisamengisztki/.local/lib/python3.10/site-packages/tables_io/ioUtils.py", line 946, in read
    odict = readNative(filepath, fmt, keys, allow_missing_keys)
  File "/home/heloisamengisztki/.local/lib/python3.10/site-packages/tables_io/ioUtils.py", line 920, in readNative
    return readPqToDataFrames(basepath, keys, allow_missing_keys)
  File "/home/heloisamengisztki/.local/lib/python3.10/site-packages/tables_io/ioUtils.py", line 782, in readPqToDataFrames
    raise FileNotFoundError from msg
FileNotFoundError
Executing stage: Inform_BPZ_lite @ 2022-10-27 01:23:28.133990
Inserting handle into data store.  input: inprogress_output_col_remapper_train.pq, inform_bpzlite
Stage failed: Inform_BPZ_lite @ 2022-10-27 01:23:28.460867 after 0.01 minutes
